<?xml version="1.0" ?>
<!-- =================================================================================== -->
<!-- |    This document was autogenerated by xacro from /media/josefajardo/Data/ROS_WS/tesis_ws/src/osf_wbc_bsc_thesis/mobile_manipulator_unal_description/urdf/mobile_manipulator.xacro | -->
<!-- |    EDITING THIS FILE BY HAND IS NOT RECOMMENDED                                 | -->
<!-- =================================================================================== -->
<robot name="mobile_robot">
  <material name="white">
    <color rgba="1.0 1.0 1.0 1.0"/>
  </material>
  <link name="mobile_manipulator/base_footprint"/>
  <!-- Fixed Joint between Base_footprint and Robot Base-->
  <joint name="base_fixed_joint" type="fixed">
    <parent link="mobile_manipulator/base_footprint"/>
    <child link="mobile_manipulator/mobile_base_link"/>
  </joint>
  <!-- Base Link description -->
  <link name="mobile_manipulator/mobile_base_link">
    <visual>
      <origin rpy="0 0 0" xyz="0 0 0.035"/>
      <geometry>
        <mesh filename="package://mobile_robot_unal_description/meshes/Robotino3_SplitMain.dae" scale="0.01 0.01 0.01"/>
      </geometry>
      <material name="white"/>
    </visual>
    <collision>
      <origin rpy="0 0 0" xyz="0 0 0.035"/>
      <geometry>
        <mesh filename="package://mobile_robot_unal_description/meshes/Robotino3_SplitMain.dae" scale="0.01 0.01 0.01"/>
      </geometry>
    </collision>
    <inertial>
      <origin rpy="0 0 0" xyz="0.002288 0.045646 0.074145"/>
      <mass value="20.0"/>
      <inertia ixx="0.258839226" ixy="0.002668446" ixz="-0.005336891" iyy="0.394929953" iyz="0.005336891" izz="0.426951301"/>
    </inertial>
  </link>
  <!-- Wheel 0 Joint (attaching mobile_base_link and wheel0_link)-->
  <joint name="wheel0_joint" type="continuous">
    <parent link="mobile_manipulator/mobile_base_link"/>
    <child link="mobile_manipulator/wheel0_link"/>
    <origin rpy="0 0 0" xyz="-0.0001 0.1825 0.059154"/>
    <axis rpy="0 0 0" xyz="0 1 0"/>
    <limit effort="200.0" velocity="23.5"/>
  </joint>
  <!-- Wheel0 Link description -->
  <link name="mobile_manipulator/wheel0_link">
    <visual>
      <origin rpy="0 0 0" xyz="0 0 0"/>
      <geometry>
        <mesh filename="package://mobile_robot_unal_description/meshes/Robotino3_SplitWheel.dae" scale="0.01 0.01 0.01"/>
      </geometry>
    </visual>
    <collision>
      <origin rpy="1.5707963267948966 0 0" xyz="0 0 0"/>
      <geometry>
        <!-- <mesh filename="package://mobile_robot_unal_description/meshes/Robotino3_SplitWheel.dae" scale="0.01 0.01 0.01"/> -->
        <!-- <cylinder radius="0.06" length="0.052"/> -->
        <sphere radius="0.06"/>
      </geometry>
    </collision>
    <inertial>
      <origin rpy="0 0 0" xyz="0.000091 -0.000123 -0.000182"/>
      <mass value="0.315"/>
      <inertia ixx="0.000353139" ixy="0.0" ixz="0.0" iyy="0.000706278" iyz="0.0" izz="0.000353139"/>
    </inertial>
  </link>
  <!-- Wheel 1 Joint (attaching mobile_base_link and wheel1_link)-->
  <joint name="wheel1_joint" type="continuous">
    <parent link="mobile_manipulator/mobile_base_link"/>
    <child link="mobile_manipulator/wheel1_link"/>
    <origin rpy="0 0 2.094395102393195" xyz="-0.157067 -0.090625 0.059154"/>
    <axis rpy="0 0 0" xyz="0 1 0"/>
    <limit effort="200.0" velocity="23.5"/>
  </joint>
  <!-- Wheel1 Link description -->
  <link name="mobile_manipulator/wheel1_link">
    <visual>
      <origin rpy="0 0 0" xyz="0 0 0"/>
      <geometry>
        <mesh filename="package://mobile_robot_unal_description/meshes/Robotino3_SplitWheel.dae" scale="0.01 0.01 0.01"/>
      </geometry>
    </visual>
    <collision>
      <origin rpy="1.5707963267948966 0 0" xyz="0 0 0"/>
      <geometry>
        <!-- <mesh filename="package://mobile_robot_unal_description/meshes/Robotino3_SplitWheel.dae" scale="0.01 0.01 0.01"/> -->
        <!-- <cylinder radius="0.06" length="0.052"/> -->
        <sphere radius="0.06"/>
      </geometry>
    </collision>
    <inertial>
      <origin rpy="0 0 0" xyz="0.000091 -0.000123 -0.000182"/>
      <mass value="0.315"/>
      <inertia ixx="0.000353139" ixy="0.0" ixz="0.0" iyy="0.000706278" iyz="0.0" izz="0.000353139"/>
    </inertial>
  </link>
  <!-- Wheel 2 Joint (attaching mobile_base_link and wheel2_link)-->
  <joint name="wheel2_joint" type="continuous">
    <parent link="mobile_manipulator/mobile_base_link"/>
    <child link="mobile_manipulator/wheel2_link"/>
    <origin rpy="0 0 -2.094395102393195" xyz="0.156867 -0.090625 0.059154"/>
    <axis rpy="0 0 0" xyz="0 1 0"/>
    <limit effort="200.0" velocity="23.5"/>
  </joint>
  <!-- Wheel2 Link description -->
  <link name="mobile_manipulator/wheel2_link">
    <visual>
      <origin rpy="0 0 0" xyz="0 0 0"/>
      <geometry>
        <mesh filename="package://mobile_robot_unal_description/meshes/Robotino3_SplitWheel.dae" scale="0.01 0.01 0.01"/>
      </geometry>
    </visual>
    <collision>
      <origin rpy="1.5707963267948966 0 0" xyz="0 0 0"/>
      <geometry>
        <!-- <mesh filename="package://mobile_robot_unal_description/meshes/Robotino3_SplitWheel.dae" scale="0.01 0.01 0.01"/> -->
        <!-- <cylinder radius="0.06" length="0.052"/> -->
        <sphere radius="0.06"/>
      </geometry>
    </collision>
    <inertial>
      <origin rpy="0 0 0" xyz="0.000091 -0.000123 -0.000182"/>
      <mass value="0.315"/>
      <inertia ixx="0.000353139" ixy="0.0" ixz="0.0" iyy="0.000706278" iyz="0.0" izz="0.000353139"/>
    </inertial>
  </link>
  <!-- IMU Joint (attaching mobile_base_link and imu_link)-->
  <joint name="imu_joint" type="fixed">
    <parent link="mobile_manipulator/mobile_base_link"/>
    <child link="mobile_manipulator/imu_link"/>
    <origin rpy="0 0 0" xyz="0.0 -0.06 0.10"/>
  </joint>
  <!-- IMU Link description -->
  <link name="mobile_manipulator/imu_link"/>
  <!-- Platform Joint (attaching mobile_base_link and wheel2_link)-->
  <joint name="platform_joint" type="fixed">
    <parent link="mobile_manipulator/mobile_base_link"/>
    <child link="mobile_manipulator/platform_link"/>
    <origin rpy="0.0 0.0 0.0" xyz="0.0 0.0 0.32"/>
  </joint>
  <link name="mobile_manipulator/platform_link">
    <visual>
      <origin rpy="0.0 0.0 0.0" xyz="0.0 0.0 -0.02"/>
      <geometry>
        <cylinder length="0.04" radius="0.2"/>
      </geometry>
      <material name="grey">
        <color rgba="0.5 0.5 0.5 1.0"/>
      </material>
    </visual>
  </link>
  <material name="interbotix_black">
    <color rgba="0.0 0.0 0.0 1.0"/>
  </material>
  <!-- Fixed Joint between Platform and Robot Base-->
  <joint name="fixed" type="fixed">
    <parent link="mobile_manipulator/platform_link"/>
    <child link="mobile_manipulator/base_link"/>
  </joint>
  <!-- Base Link description-->
  <link name="mobile_manipulator/base_link">
    <visual>
      <origin rpy="0 0 1.5707963267948966" xyz="0 0 0"/>
      <geometry>
        <mesh filename="package://manipulator_unal_description/meshes/VXSA-300-M-1-Base.stl" scale="0.001 0.001 0.001"/>
      </geometry>
      <material name="interbotix_black"/>
    </visual>
    <collision>
      <origin rpy="0 0 1.5707963267948966" xyz="0 0 0"/>
      <geometry>
        <mesh filename="package://manipulator_unal_description/meshes/VXSA-300-M-1-Base.stl" scale="0.001 0.001 0.001"/>
      </geometry>
    </collision>
    <inertial>
      <origin rpy="0 0 1.5707963267948966" xyz="-0.0534774000 -0.0005625750 0.0205961000"/>
      <mass value="0.969034"/>
      <inertia ixx="0.0060240000" ixy="0.0000471300" ixz="0.0000038510" iyy="0.0017000000" iyz="-0.0000841500" izz="0.0071620000"/>
    </inertial>
  </link>
  <!-- Waist Joint (attaching waist_link and shoulder_link)-->
  <joint name="waist_joint" type="revolute">
    <axis xyz="0 0 1"/>
    <limit effort="10.6" lower="-3.141592653589793" upper="3.141592653589793" velocity="3.1"/>
    <origin rpy="0 0 0" xyz="0 0 0.0787"/>
    <parent link="mobile_manipulator/base_link"/>
    <child link="mobile_manipulator/shoulder_link"/>
  </joint>
  <!-- Shoulder Link description-->
  <link name="mobile_manipulator/shoulder_link">
    <visual>
      <origin rpy="0 0 1.5707963267948966" xyz="0 0 -0.003"/>
      <geometry>
        <mesh filename="package://manipulator_unal_description/meshes/VXSA-300-M-2-Shoulder.stl" scale="0.001 0.001 0.001"/>
      </geometry>
      <material name="interbotix_black"/>
    </visual>
    <collision>
      <origin rpy="0 0 1.5707963267948966" xyz="0 0 -0.003"/>
      <geometry>
        <mesh filename="package://manipulator_unal_description/meshes/VXSA-300-M-2-Shoulder.stl" scale="0.001 0.001 0.001"/>
      </geometry>
    </collision>
    <inertial>
      <origin rpy="0 0 1.5707963267948966" xyz="0.0002592330 -0.0000033552 0.0116129000"/>
      <mass value="0.798614"/>
      <inertia ixx="0.0009388000" ixy="-0.0000000010" ixz="-0.0000000191" iyy="0.0011380000" iyz="0.0000059568" izz="0.0012010000"/>
    </inertial>
  </link>
  <!-- Shoulder Joint (attaching shoulder_link and upper_arm_link)-->
  <joint name="shoulder_joint" type="revolute">
    <axis xyz="0 0 1"/>
    <limit effort="21.2" lower="-1.8500490071139892" upper="1.7627825445142729" velocity="3.1"/>
    <origin rpy="-1.5707963267948966 0 0" xyz="0 0 0.04805"/>
    <parent link="mobile_manipulator/shoulder_link"/>
    <child link="mobile_manipulator/upper_arm_link"/>
  </joint>
  <!-- Upper Arm Link description -->
  <link name="mobile_manipulator/upper_arm_link">
    <visual>
      <origin rpy="1.5707963267948966 -1.5707963267948966 0" xyz="0 0 0"/>
      <geometry>
        <mesh filename="package://manipulator_unal_description/meshes/VXSA-300-M-3-UA.stl" scale="0.001 0.001 0.001"/>
      </geometry>
      <material name="interbotix_black"/>
    </visual>
    <collision>
      <origin rpy="1.5707963267948966 -1.5707963267948966 0" xyz="0 0 0"/>
      <geometry>
        <mesh filename="package://manipulator_unal_description/meshes/VXSA-300-M-3-UA.stl" scale="0.001 0.001 0.001"/>
      </geometry>
    </collision>
    <inertial>
      <origin rpy="1.5707963267948966 -1.5707963267948966 0" xyz="0.0206949000 -0.2264590000 0.0000000004"/>
      <mass value="0.792592"/>
      <inertia ixx="0.0089250000" ixy="0.0000000000" ixz="0.0000000000" iyy="0.0089370000" iyz="0.0012010000" izz="0.0009357000"/>
    </inertial>
  </link>
  <!-- Elbow Joint (attaching upper_arm_link and upper_forearm_link)-->
  <joint name="elbow_joint" type="revolute">
    <axis xyz="0 0 1"/>
    <limit effort="21.2" lower="-1.6057029118347832" upper="1.7627825445142729" velocity="3.1"/>
    <origin rpy="3.141592653589793 0 -1.5707963267948966" xyz="0.05955 -0.3 0.0"/>
    <parent link="mobile_manipulator/upper_arm_link"/>
    <child link="mobile_manipulator/upper_forearm_link"/>
  </joint>
  <!-- Upper Forearm Link description -->
  <link name="mobile_manipulator/upper_forearm_link">
    <visual>
      <origin rpy="1.5707963267948966 0 -1.5707963267948966" xyz="0 0 0"/>
      <geometry>
        <mesh filename="package://manipulator_unal_description/meshes/VXSA-300-M-4-UF.stl" scale="0.001 0.001 0.001"/>
      </geometry>
      <material name="interbotix_black"/>
    </visual>
    <collision>
      <origin rpy="1.5707963267948966 0 -1.5707963267948966" xyz="0 0 0"/>
      <geometry>
        <mesh filename="package://manipulator_unal_description/meshes/VXSA-300-M-4-UF.stl" scale="0.001 0.001 0.001"/>
      </geometry>
    </collision>
    <inertial>
      <origin rpy="1.5707963267948966 0 -1.5707963267948966" xyz="0 -0.105723 0"/>
      <mass value="0.322228"/>
      <inertia ixx="0.0001524000" ixy="-0.0000188300" ixz="-0.0000084064" iyy="0.0013420000" iyz="0.0000012564" izz="0.0014410000"/>
    </inertial>
  </link>
  <!-- Upper Forearm Joint (attaching upper_forearm_link and lowe_forearm_link)-->
  <joint name="upper_forearm_joint" type="revolute">
    <axis xyz="0 0 1"/>
    <limit effort="10.6" lower="-3.141592653589793" upper="3.141592653589793" velocity="3.1"/>
    <origin rpy="1.5707963267948966 0 0" xyz="0 -0.2 0"/>
    <parent link="mobile_manipulator/upper_forearm_link"/>
    <child link="mobile_manipulator/lower_forearm_link"/>
  </joint>
  <!-- Lower Forearm Link description -->
  <link name="mobile_manipulator/lower_forearm_link">
    <visual>
      <origin rpy="0 -1.5707963267948966 0" xyz="0 0 0"/>
      <geometry>
        <mesh filename="package://manipulator_unal_description/meshes/VXSA-300-M-5-LF.stl" scale="0.001 0.001 0.001"/>
      </geometry>
      <material name="interbotix_black"/>
    </visual>
    <collision>
      <origin rpy="0 -1.5707963267948966 0" xyz="0 0 0"/>
      <geometry>
        <mesh filename="package://manipulator_unal_description/meshes/VXSA-300-M-5-LF.stl" scale="0.001 0.001 0.001"/>
      </geometry>
    </collision>
    <inertial>
      <origin rpy="0 -1.5707963267948966 0" xyz="0 -0.0068046200 0.0513477000"/>
      <mass value="0.414823"/>
      <inertia ixx="0.0001753000" ixy="-0.0000852800" ixz="0" iyy="0.0005269000" iyz="0" izz="0.0005911000"/>
    </inertial>
  </link>
  <!-- Lower Forearm Joint (attaching lower_forearm_link and wrist_link)-->
  <joint name="lower_forearm_joint" type="revolute">
    <axis xyz="0 0 1"/>
    <limit effort="10.6" lower="-2.2689280275926285" upper="1.8675022996339325" velocity="3.1"/>
    <origin rpy="-1.5707963267948966 0 0" xyz="0 0 0.1"/>
    <parent link="mobile_manipulator/lower_forearm_link"/>
    <child link="mobile_manipulator/wrist_link"/>
  </joint>
  <!-- Wrist Link Description-->
  <link name="mobile_manipulator/wrist_link">
    <visual>
      <origin rpy="0 1.5707963267948966 0" xyz="0 0 0"/>
      <geometry>
        <mesh filename="package://manipulator_unal_description/meshes/VXSA-300-M-6-Wrist.stl" scale="0.001 0.001 0.001"/>
      </geometry>
      <material name="interbotix_black"/>
    </visual>
    <collision>
      <origin rpy="0 1.5707963267948966 0" xyz="0 0 0"/>
      <geometry>
        <mesh filename="package://manipulator_unal_description/meshes/VXSA-300-M-6-Wrist.stl" scale="0.001 0.001 0.001"/>
      </geometry>
    </collision>
    <inertial>
      <origin rpy="0 1.5707963267948966 0" xyz="0.0105650000 -0.0467430000 0.0000076652"/>
      <mass value="0.115395"/>
      <inertia ixx="0.0000463100" ixy="0.0000000195" ixz="0.0000000023" iyy="0.0000451400" iyz="0.0000042002" izz="0.0000527000"/>
    </inertial>
  </link>
  <!-- Wrist Joint (attaching wrist_link and gripper)-->
  <joint name="wrist_joint" type="revolute">
    <axis xyz="0 0 1"/>
    <limit effort="4.1" lower="-3.141592653589793" upper="3.141592653589793" velocity="3.1"/>
    <origin rpy="1.5707963267948966 3.141592653589793 0" xyz="0 -0.069744 0"/>
    <parent link="mobile_manipulator/wrist_link"/>
    <child link="mobile_manipulator/base_gripper_link"/>
  </joint>
  <!-- Base Gripper Link Description-->
  <link name="mobile_manipulator/base_gripper_link">
    <visual>
      <origin rpy="1.5707963267948966 3.141592653589793 -1.5707963267948966" xyz="0 0 -0.02"/>
      <geometry>
        <mesh filename="package://manipulator_unal_description/meshes/VXSA-300-M-7-Gripper.stl" scale="0.001 0.001 0.001"/>
      </geometry>
      <material name="interbotix_black"/>
    </visual>
    <collision>
      <origin rpy="1.5707963267948966 3.141592653589793 -1.5707963267948966" xyz="-0.02 0 0"/>
      <geometry>
        <mesh filename="package://manipulator_unal_description/meshes/VXSA-300-M-7-Gripper.stl" scale="0.001 0.001 0.001"/>
      </geometry>
    </collision>
    <inertial>
      <origin rpy="1.5707963267948966 3.141592653589793 -1.5707963267948966" xyz="-0.0115230000  0.0000000000 0.0230010000"/>
      <mass value="0.097666"/>
      <inertia ixx="0.0000326800" ixy="0.0000000000" ixz="0.0000000000" iyy="0.0000243600" iyz="0.0000002785" izz="0.0000211900"/>
    </inertial>
  </link>
  <!-- Fixed joint to End Effector-->
  <joint name="tcp_joint" type="fixed">
    <origin rpy="0 -1.5707963267948966 0" xyz="0.0 0 0.042825"/>
    <parent link="mobile_manipulator/base_gripper_link"/>
    <child link="mobile_manipulator/end_effector_link"/>
  </joint>
  <!-- End Effector Frame-->
  <link name="mobile_manipulator/end_effector_link">
    <inertial>
      <mass value="0.001"/>
      <inertia ixx="0.0001" ixy="0" ixz="0" iyy="0.0001" iyz="0" izz="0.0001"/>
    </inertial>
  </link>
  <!-- ############################################################################################# -->
  <!-- ############################################################################################# -->
  <!-- ############################################################################################# -->
  <!-- Joint between EE and Gripper Prop (Prop of gripper motor) -->
  <joint name="gripper_joint" type="fixed">
    <!-- continuous-->
    <axis xyz="1 0 0"/>
    <limit effort="100" velocity="3.141592653589793"/>
    <origin rpy="0 0 0" xyz="0.005675 0 0"/>
    <parent link="mobile_manipulator/end_effector_link"/>
    <child link="mobile_manipulator/gripper_prop_link"/>
  </joint>
  <!-- Gripper Prop Link Description-->
  <link name="mobile_manipulator/gripper_prop_link">
    <visual>
      <origin rpy="0 0 1.5707963267948966" xyz="-0.0685 0 0"/>
      <geometry>
        <mesh filename="package://manipulator_unal_description/meshes/VXSA-300-M-8-Gripper-Prop.stl" scale="0.001 0.001 0.001"/>
      </geometry>
      <material name="interbotix_black"/>
    </visual>
    <collision>
      <origin rpy="0 0 1.5707963267948966" xyz="-0.0685 0 0"/>
      <geometry>
        <mesh filename="package://manipulator_unal_description/meshes/VXSA-300-M-8-Gripper-Prop.stl" scale="0.001 0.001 0.001"/>
      </geometry>
    </collision>
    <inertial>
      <origin rpy="0 0 1.5707963267948966" xyz="0.0023780000 0.0000000285 0.0000000000"/>
      <mass value="0.008009"/>
      <inertia ixx="0.0000020386" ixy="0.0000000000" ixz="0.0000006559" iyy="0.0000042979" iyz="0.0000000000" izz="0.0000023796"/>
    </inertial>
  </link>
  <!-- Gripper Bar Fixed Joint (attaching EE and gripper bar)-->
  <joint name="gripper_bar_joint" type="fixed">
    <axis xyz="1 0 0"/>
    <origin rpy="0 0 0" xyz="0 0 0"/>
    <parent link="mobile_manipulator/end_effector_link"/>
    <child link="mobile_manipulator/gripper_bar_link"/>
  </joint>
  <!-- Gripper Bar Link Description-->
  <link name="mobile_manipulator/gripper_bar_link">
    <visual>
      <origin rpy="0 0 1.5707963267948966" xyz="-0.063 0 0"/>
      <geometry>
        <mesh filename="package://manipulator_unal_description/meshes/VXSA-300-M-9-Gripper-Bar.stl" scale="0.001 0.001 0.001"/>
      </geometry>
      <material name="interbotix_black"/>
    </visual>
    <collision>
      <origin rpy="0 0 1.5707963267948966" xyz="-0.063 0 0"/>
      <geometry>
        <mesh filename="package://manipulator_unal_description/meshes/VXSA-300-M-9-Gripper-Bar.stl" scale="0.001 0.001 0.001"/>
      </geometry>
    </collision>
    <inertial>
      <origin rpy="0 0 1.5707963267948966" xyz="0.0067940000 -0.0000004272 -0.0007760000"/>
      <mass value="0.150986"/>
      <inertia ixx="0.0000789500" ixy="-0.0000000012" ixz="0.0000001341" iyy="0.0003283000" iyz="0.0000017465" izz="0.0003095000"/>
    </inertial>
  </link>
  <!-- Fixed joint bewteen bar link and TCP of the bar-->
  <joint name="tcp_bar" type="fixed">
    <axis xyz="1 0 0"/>
    <origin rpy="0 0 0" xyz="0.025875 0 0"/>
    <parent link="mobile_manipulator/gripper_bar_link"/>
    <child link="mobile_manipulator/tcp_bar_link"/>
  </joint>
  <!-- TCP of the gripper bar Link Description-->
  <link name="mobile_manipulator/tcp_bar_link">
    <inertial>
      <mass value="0.001"/>
      <inertia ixx="0.0001" ixy="0.0" ixz="0.0" iyy="0.0001" iyz="0.0" izz="0.0001"/>
    </inertial>
  </link>
  <!-- ############################################################################################# -->
  <!-- ############################################################################################# -->
  <!-- Left Finger Joint ( Attaching the gripper bar TCP to the left finger link)-->
  <joint name="left_finger_joint" type="prismatic">
    <axis xyz="0 1 0"/>
    <limit effort="10" lower="-0.018" upper="0.018" velocity="1"/>
    <origin rpy="0 0 0" xyz="0 0.039 0"/>
    <parent link="mobile_manipulator/tcp_bar_link"/>
    <child link="mobile_manipulator/left_finger_link"/>
  </joint>
  <!-- Left Finger Link description-->
  <link name="mobile_manipulator/left_finger_link">
    <visual>
      <origin rpy="1.5707963267948966 -3.141592653589793 1.5707963267948966" xyz="-0.0404 -0.0575 0"/>
      <geometry>
        <mesh filename="package://manipulator_unal_description/meshes/VXSA-300-M-10-Finger.stl" scale="0.001 0.001 0.001"/>
      </geometry>
      <material name="interbotix_black"/>
    </visual>
    <collision>
      <origin rpy="1.5707963267948966 -3.141592653589793 1.5707963267948966" xyz="-0.0404 -0.0575 0"/>
      <geometry>
        <mesh filename="package://manipulator_unal_description/meshes/VXSA-300-M-10-Finger.stl" scale="0.001 0.001 0.001"/>
      </geometry>
    </collision>
    <inertial>
      <origin rpy="3.141592653589793 3.141592653589793 1.5707963267948966" xyz="0.0173440000 -0.0060692000 0.0000000000"/>
      <mass value="0.034796"/>
      <inertia ixx="0.0000243300" ixy="-0.0000024004" ixz="0.0000000000" iyy="0.0000125500" iyz="0.0000000000" izz="0.0000141700"/>
    </inertial>
  </link>
  <!-- Right Finger Joint ( Attaching the gripper bar TCP to the right finger link)-->
  <joint name="right_finger_joint" type="prismatic">
    <axis xyz="0 1 0"/>
    <limit effort="10" lower="-0.018" upper="0.018" velocity="1"/>
    <origin rpy="0 0 0" xyz="0 -0.039 0"/>
    <parent link="mobile_manipulator/tcp_bar_link"/>
    <child link="mobile_manipulator/right_finger_link"/>
  </joint>
  <!-- Right Finger Link description -->
  <link name="mobile_manipulator/right_finger_link">
    <visual>
      <origin rpy="-1.5707963267948966 3.141592653589793 -1.5707963267948966" xyz="-0.0404 0.0575 0 "/>
      <geometry>
        <mesh filename="package://manipulator_unal_description/meshes/VXSA-300-M-10-Finger.stl" scale="0.001 0.001 0.001"/>
      </geometry>
      <material name="interbotix_black"/>
    </visual>
    <collision>
      <origin rpy="-1.5707963267948966 3.141592653589793 -1.5707963267948966" xyz="-0.0404 0.0575 0 "/>
      <geometry>
        <mesh filename="package://manipulator_unal_description/meshes/VXSA-300-M-10-Finger.stl" scale="0.001 0.001 0.001"/>
      </geometry>
    </collision>
    <inertial>
      <origin rpy="0 3.141592653589793 1.5707963267948966" xyz="0.0173440000 0.0060692000  0.0000000000"/>
      <mass value="0.034796"/>
      <inertia ixx="0.0000243300" ixy="0.0000024001" ixz="0.0000000000" iyy="0.0000125500" iyz="0.0000000000" izz="0.0000141700"/>
    </inertial>
  </link>
  <!-- Fixed joint attaching the gripper bar TCP frame to the gripper TCP-->
  <joint name="tcp_gripper_joint" type="fixed">
    <axis xyz="1 0 0"/>
    <origin rpy="0 0 0" xyz="0.0385 0 0"/>
    <parent link="mobile_manipulator/tcp_bar_link"/>
    <child link="mobile_manipulator/tcp_gripper_link"/>
  </joint>
  <!-- Gripper TCP Link description-->
  <link name="mobile_manipulator/tcp_gripper_link">
    <inertial>
      <mass value="0.001"/>
      <inertia ixx="0.0001" ixy="0" ixz="0" iyy="0.0001" iyz="0" izz="0.0001"/>
    </inertial>
  </link>
  <!-- Waist Tranmission -->
  <transmission name="trans_waist">
    <type>transmission_interface/SimpleTransmission</type>
    <joint name="waist_joint">
      <hardwareInterface>hardware_interface/EffortJointInterface</hardwareInterface>
    </joint>
    <actuator name="waist_motor">
      <mechanicalReduction>1</mechanicalReduction>
    </actuator>
  </transmission>
  <!-- Shoulder Tranmission -->
  <transmission name="trans_shoulder">
    <type>transmission_interface/SimpleTransmission</type>
    <joint name="shoulder_joint">
      <hardwareInterface>hardware_interface/EffortJointInterface</hardwareInterface>
    </joint>
    <actuator name="shoulder_motor">
      <mechanicalReduction>1</mechanicalReduction>
    </actuator>
  </transmission>
  <!-- Elbow Tranmission -->
  <transmission name="trans_elbow">
    <type>transmission_interface/SimpleTransmission</type>
    <joint name="elbow_joint">
      <hardwareInterface>hardware_interface/EffortJointInterface</hardwareInterface>
    </joint>
    <actuator name="elbow_motor">
      <mechanicalReduction>1</mechanicalReduction>
    </actuator>
  </transmission>
  <!-- Upper Forearm Tranmission -->
  <transmission name="trans_upper_forearm">
    <type>transmission_interface/SimpleTransmission</type>
    <joint name="upper_forearm_joint">
      <hardwareInterface>hardware_interface/EffortJointInterface</hardwareInterface>
    </joint>
    <actuator name="upper_forearm_motor">
      <mechanicalReduction>1</mechanicalReduction>
    </actuator>
  </transmission>
  <!-- Lower Forearm Tranmission -->
  <transmission name="trans_lower_forearm_joint">
    <type>transmission_interface/SimpleTransmission</type>
    <joint name="lower_forearm_joint">
      <hardwareInterface>hardware_interface/EffortJointInterface</hardwareInterface>
    </joint>
    <actuator name="lower_forearm_joint_motor">
      <mechanicalReduction>1</mechanicalReduction>
    </actuator>
  </transmission>
  <!-- Wrist Tranmission -->
  <transmission name="trans_wrist_joint">
    <type>transmission_interface/SimpleTransmission</type>
    <joint name="wrist_joint">
      <hardwareInterface>hardware_interface/EffortJointInterface</hardwareInterface>
    </joint>
    <actuator name="wrist_joint_motor">
      <mechanicalReduction>1</mechanicalReduction>
    </actuator>
  </transmission>
  <!-- Gripper Prop Tranmission 
    <transmission name="trans_gripper">
        <type>transmission_interface/SimpleTransmission</type>
        <joint name="gripper_joint">
            <hardwareInterface>hardware_interface/EffortJointInterface</hardwareInterface>
        </joint>
        <actuator name="gripper_motor">
            <mechanicalReduction>1</mechanicalReduction>
        </actuator>
    </transmission>
    -->
  <!-- Left Finger Tranmission -->
  <transmission name="trans_left_finger">
    <type>transmission_interface/SimpleTransmission</type>
    <joint name="left_finger_joint">
      <hardwareInterface>hardware_interface/EffortJointInterface</hardwareInterface>
    </joint>
    <actuator name="left_finger_motor">
      <mechanicalReduction>1</mechanicalReduction>
    </actuator>
  </transmission>
  <!-- Right Finger Tranmission -->
  <transmission name="trans_right_finger">
    <type>transmission_interface/SimpleTransmission</type>
    <joint name="right_finger_joint">
      <hardwareInterface>hardware_interface/EffortJointInterface</hardwareInterface>
    </joint>
    <actuator name="right_finger_motor">
      <mechanicalReduction>1</mechanicalReduction>
    </actuator>
  </transmission>
  <gazebo reference="mobile_manipulator/base_link">
    <material>Gazebo/Black</material>
    <selfCollide>True</selfCollide>
  </gazebo>
  <gazebo reference="mobile_manipulator/shoulder_link">
    &gt;
        
    <material>Gazebo/Blue</material>
    <selfCollide>True</selfCollide>
  </gazebo>
  <gazebo reference="mobile_manipulator/upper_arm_link">
    <material>Gazebo/DarkGrey</material>
    <selfCollide>True</selfCollide>
  </gazebo>
  <gazebo reference="mobile_manipulator/upper_forearm_link">
    <material>Gazebo/Orange</material>
    <selfCollide>True</selfCollide>
  </gazebo>
  <gazebo reference="mobile_manipulator/lower_forearm_link">
    <material>Gazebo/Grey</material>
    <selfCollide>True</selfCollide>
  </gazebo>
  <gazebo reference="mobile_manipulator/wrist_link">
    <material>Gazebo/Indigo</material>
    <selfCollide>True</selfCollide>
  </gazebo>
  <gazebo reference="mobile_manipulator/base_gripper_link">
    <material>Gazebo/Black</material>
    <selfCollide>True</selfCollide>
  </gazebo>
  <gazebo reference="mobile_manipulator/gripper_bar_link">
    <material>Gazebo/Green</material>
    <selfCollide>True</selfCollide>
  </gazebo>
  <gazebo reference="mobile_manipulator/left_finger_link">
    <material>Gazebo/Red</material>
    <selfCollide>True</selfCollide>
  </gazebo>
  <gazebo reference="mobile_manipulator/right_finger_link">
    <material>Gazebo/Red</material>
    <selfCollide>True</selfCollide>
  </gazebo>
  <!--  disableFixedJointLumping  
    <gazebo reference="tcp_joint">
        <disableFixedJointLumping>true</disableFixedJointLumping>
    </gazebo>
    
    <gazebo reference="gripper_bar_joint">
        <disableFixedJointLumping>true</disableFixedJointLumping>
    </gazebo>
    
    <gazebo reference="tcp_bar">
        <disableFixedJointLumping>true</disableFixedJointLumping>
    </gazebo>
    
    <gazebo reference="tcp_gripper_joint">
        <disableFixedJointLumping>true</disableFixedJointLumping>
    </gazebo>
    -->
  <!-- Wheel0 Tranmission -->
  <transmission name="trans_wheel0">
    <type>transmission_interface/SimpleTransmission</type>
    <joint name="wheel0_joint">
      <hardwareInterface>hardware_interface/VelocityJointInterface</hardwareInterface>
    </joint>
    <actuator name="wheel0_motor">
      <mechanicalReduction>1</mechanicalReduction>
    </actuator>
  </transmission>
  <!-- Wheel1 Tranmission -->
  <transmission name="trans_wheel1">
    <type>transmission_interface/SimpleTransmission</type>
    <joint name="wheel1_joint">
      <hardwareInterface>hardware_interface/VelocityJointInterface</hardwareInterface>
    </joint>
    <actuator name="wheel1_motor">
      <mechanicalReduction>1</mechanicalReduction>
    </actuator>
  </transmission>
  <!-- Wheel2 Tranmission -->
  <transmission name="trans_wheel2">
    <type>transmission_interface/SimpleTransmission</type>
    <joint name="wheel2_joint">
      <hardwareInterface>hardware_interface/VelocityJointInterface</hardwareInterface>
    </joint>
    <actuator name="wheel2_motor">
      <mechanicalReduction>1</mechanicalReduction>
    </actuator>
  </transmission>
  <gazebo>
    <plugin filename="libgazebo_ros_control.so" name="gazebo_ros_control">
      <robotSimType>gazebo_ros_control/DefaultRobotHWSim</robotSimType>
    </plugin>
  </gazebo>
  <gazebo reference="mobile_manipulator/wheel0_link">
    <mu1>0.01</mu1>
    <mu2>1</mu2>
    <fdir1>0 0 1</fdir1>
  </gazebo>
  <gazebo reference="mobile_manipulator/wheel1_link">
    <mu1>0.01</mu1>
    <mu2>1</mu2>
    <fdir1>0 0 1</fdir1>
  </gazebo>
  <gazebo reference="mobile_manipulator/wheel2_link">
    <mu1>0.01</mu1>
    <mu2>1</mu2>
    <fdir1>0 0 1</fdir1>
  </gazebo>
  <gazebo>
    <plugin filename="libgazebo_ros_imu.so" name="imu_plugin">
      <alwaysOn>true</alwaysOn>
      <bodyName>mobile_manipulator/imu_link</bodyName>
      <topicName>imu_data</topicName>
      <serviceName>imu_service</serviceName>
      <gaussianNoise>0.05</gaussianNoise>
      <updateRate>200.0</updateRate>
    </plugin>
  </gazebo>
</robot>
