<?xml version="1.0" encoding="utf-8"?>
<!-- =================================================================================== -->
<!-- |    This document was autogenerated by xacro from /home/josefajardo/catkin_ws/src/tesis_2020/manipulator_unal_description/urdf/manipulator.xacro | -->
<!-- |    EDITING THIS FILE BY HAND IS NOT RECOMMENDED                                 | -->
<!-- =================================================================================== -->
<robot name="manipulator">
  <material name="interbotix_black">
    <color rgba="0.0 0.0 0.0 1.0"/>
  </material>
  <!-- World Frame-->
  <link name="world"/>
  <!-- Fixed Joint between World and Robot Base-->
  <joint name="fixed" type="fixed">
    <parent link="world"/>
    <child link="manipulator/base_link"/>
  </joint>
  <!-- Base Link description-->
  <link name="manipulator/base_link">
    <visual>
      <origin rpy="0 0 1.57079632679" xyz="0 0 0"/>
      <geometry>
        <mesh filename="package://manipulator_unal_description/meshes/VXSA-300-M-1-Base.stl" scale="0.001 0.001 0.001"/>
      </geometry>
      <material name="interbotix_black"/>
    </visual>
    <collision>
      <origin rpy="0 0 1.57079632679" xyz="0 0 0"/>
      <geometry>
        <mesh filename="package://manipulator_unal_description/meshes/VXSA-300-M-1-Base.stl" scale="0.001 0.001 0.001"/>
      </geometry>
    </collision>
    <inertial>
      <origin rpy="0 0 1.57079632679" xyz="-0.0534774000 -0.0005625750 0.0205961000"/>
      <mass value="0.969034"/>
      <inertia ixx="0.0060240000" ixy="0.0000471300" ixz="0.0000038510" iyy="0.0017000000" iyz="-0.0000841500" izz="0.0071620000"/>
    </inertial>
  </link>
  <!-- Waist Joint (attaching waist_link and shoulder_link)-->
  <joint name="waist_joint" type="revolute">
    <axis xyz="0 0 1"/>
    <limit effort="100" lower="-3.14159265359" upper="3.14159265359" velocity="3.14159265359"/>
    <origin rpy="0 0 0" xyz="0 0 0.0787"/>
    <parent link="manipulator/base_link"/>
    <child link="manipulator/shoulder_link"/>
  </joint>
  <!-- Shoulder Link description-->
  <link name="manipulator/shoulder_link">
    <visual>
      <origin rpy="0 0 1.57079632679" xyz="0 0 -0.003"/>
      <geometry>
        <mesh filename="package://manipulator_unal_description/meshes/VXSA-300-M-2-Shoulder.stl" scale="0.001 0.001 0.001"/>
      </geometry>
      <material name="interbotix_black"/>
    </visual>
    <collision>
      <origin rpy="0 0 1.57079632679" xyz="0 0 -0.003"/>
      <geometry>
        <mesh filename="package://manipulator_unal_description/meshes/VXSA-300-M-2-Shoulder.stl" scale="0.001 0.001 0.001"/>
      </geometry>
    </collision>
    <inertial>
      <origin rpy="0 0 1.57079632679" xyz="0.0002592330 -0.0000033552 0.0116129000"/>
      <mass value="0.798614"/>
      <inertia ixx="0.0009388000" ixy="-0.0000000010" ixz="-0.0000000191" iyy="0.0011380000" iyz="0.0000059568" izz="0.0012010000"/>
    </inertial>
  </link>
  <!-- Shoulder Joint (attaching shoulder_link and upper_arm_link)-->
  <joint name="shoulder_joint" type="revolute">
    <axis xyz="0 1 0"/>
    <limit effort="100" lower="-1.85004900711" upper="1.76278254451" velocity="3.14159265359"/>
    <origin rpy="0 0 0" xyz="0 0 0.04805"/>
    <parent link="manipulator/shoulder_link"/>
    <child link="manipulator/upper_arm_link"/>
  </joint>
  <!-- Upper Arm Link description -->
  <link name="manipulator/upper_arm_link">
    <visual>
      <origin rpy="0 0 1.57079632679" xyz="0 0 0"/>
      <geometry>
        <mesh filename="package://manipulator_unal_description/meshes/VXSA-300-M-3-UA.stl" scale="0.001 0.001 0.001"/>
      </geometry>
      <material name="interbotix_black"/>
    </visual>
    <collision>
      <origin rpy="0 0 1.57079632679" xyz="0 0 0"/>
      <geometry>
        <mesh filename="package://manipulator_unal_description/meshes/VXSA-300-M-3-UA.stl" scale="0.001 0.001 0.001"/>
      </geometry>
    </collision>
    <inertial>
      <origin rpy="0 0 1.57079632679" xyz="0.0206949000 0.0000000004 0.2264590000"/>
      <mass value="0.792592"/>
      <inertia ixx="0.0089250000" ixy="0.0000000000" ixz="0.0000000000" iyy="0.0089370000" iyz="0.0012010000" izz="0.0009357000"/>
    </inertial>
  </link>
  <!-- Elbow Joint (attaching upper_arm_link and upper_forearm_link)-->
  <joint name="elbow_joint" type="revolute">
    <axis xyz="0 1 0"/>
    <limit effort="100" lower="-1.60570291183" upper="1.76278254451" velocity="3.14159265359"/>
    <origin rpy="3.14159265359 0 0" xyz="0.05955 0 0.3"/>
    <parent link="manipulator/upper_arm_link"/>
    <child link="manipulator/upper_forearm_link"/>
  </joint>
  <!-- Upper Forearm Link description -->
  <link name="manipulator/upper_forearm_link">
    <visual>
      <origin rpy="0 0 0" xyz="0 0 0"/>
      <geometry>
        <mesh filename="package://manipulator_unal_description/meshes/VXSA-300-M-4-UF.stl" scale="0.001 0.001 0.001"/>
      </geometry>
      <material name="interbotix_black"/>
    </visual>
    <collision>
      <origin rpy="0 0 0" xyz="0 0 0"/>
      <geometry>
        <mesh filename="package://manipulator_unal_description/meshes/VXSA-300-M-4-UF.stl" scale="0.001 0.001 0.001"/>
      </geometry>
    </collision>
    <inertial>
      <origin rpy="0 0 0" xyz="0.105723 0 0"/>
      <mass value="0.322228"/>
      <inertia ixx="0.0001524000" ixy="-0.0000188300" ixz="-0.0000084064" iyy="0.0013420000" iyz="0.0000012564" izz="0.0014410000"/>
    </inertial>
  </link>
  <!-- Upper Forearm Joint (attaching upper_forearm_link and lowe_forearm_link)-->
  <joint name="upper_forearm_joint" type="revolute">
    <axis xyz="1 0 0"/>
    <limit effort="100" lower="-3.14159265359" upper="3.14159265359" velocity="3.14159265359"/>
    <origin rpy="0 0 0" xyz="0.2 0 0"/>
    <parent link="manipulator/upper_forearm_link"/>
    <child link="manipulator/lower_forearm_link"/>
  </joint>
  <!-- Lower Forearm Link description -->
  <link name="manipulator/lower_forearm_link">
    <visual>
      <origin rpy="0 0 0" xyz="0 0 0"/>
      <geometry>
        <mesh filename="package://manipulator_unal_description/meshes/VXSA-300-M-5-LF.stl" scale="0.001 0.001 0.001"/>
      </geometry>
      <material name="interbotix_black"/>
    </visual>
    <collision>
      <origin rpy="0 0 0" xyz="0 0 0"/>
      <geometry>
        <mesh filename="package://manipulator_unal_description/meshes/VXSA-300-M-5-LF.stl" scale="0.001 0.001 0.001"/>
      </geometry>
    </collision>
    <inertial>
      <origin rpy="0 0 0" xyz="0.0513477000 -0.0068046200 0"/>
      <mass value="0.414823"/>
      <inertia ixx="0.0001753000" ixy="-0.0000852800" ixz="0" iyy="0.0005269000" iyz="0" izz="0.0005911000"/>
    </inertial>
  </link>
  <!-- Lower Forearm Joint (attaching lower_forearm_link and wrist_link)-->
  <joint name="lower_forearm_joint" type="revolute">
    <axis xyz="0 1 0"/>
    <limit effort="100" lower="-2.26892802759" upper="1.86750229963" velocity="3.14159265359"/>
    <origin rpy="0 0 0" xyz="0.1 0 0"/>
    <parent link="manipulator/lower_forearm_link"/>
    <child link="manipulator/wrist_link"/>
  </joint>
  <!-- Wrist Link Description-->
  <link name="manipulator/wrist_link">
    <visual>
      <origin rpy="0 3.14159265359 1.57079632679" xyz="0 0 0"/>
      <geometry>
        <mesh filename="package://manipulator_unal_description/meshes/VXSA-300-M-6-Wrist.stl" scale="0.001 0.001 0.001"/>
      </geometry>
      <material name="interbotix_black"/>
    </visual>
    <collision>
      <origin rpy="0 3.14159265359 1.57079632679" xyz="0 0 0"/>
      <geometry>
        <mesh filename="package://manipulator_unal_description/meshes/VXSA-300-M-6-Wrist.stl" scale="0.001 0.001 0.001"/>
      </geometry>
    </collision>
    <inertial>
      <origin rpy="0 3.14159265359 1.57079632679" xyz="0.0467430000 0.0000076652 -0.0105650000"/>
      <mass value="0.115395"/>
      <inertia ixx="0.0000463100" ixy="0.0000000195" ixz="0.0000000023" iyy="0.0000451400" iyz="0.0000042002" izz="0.0000527000"/>
    </inertial>
  </link>
  <!-- Wrist Joint (attaching wrist_link and gripper)-->
  <joint name="wrist_joint" type="revolute">
    <axis xyz="1 0 0"/>
    <limit effort="100" lower="-3.14159265359" upper="3.14159265359" velocity="3.14159265359"/>
    <origin rpy="-3.14159265359 0 0" xyz="0.069744 0 0"/>
    <parent link="manipulator/wrist_link"/>
    <child link="manipulator/base_gripper_link"/>
  </joint>
  <!-- Base Gripper Link Description-->
  <link name="manipulator/base_gripper_link">
    <visual>
      <origin rpy="0 0 1.57079632679" xyz="-0.02 0 0"/>
      <geometry>
        <mesh filename="package://manipulator_unal_description/meshes/VXSA-300-M-7-Gripper.stl" scale="0.001 0.001 0.001"/>
      </geometry>
      <material name="interbotix_black"/>
    </visual>
    <collision>
      <origin rpy="0 0 1.57079632679" xyz="-0.02 0 0"/>
      <geometry>
        <mesh filename="package://manipulator_unal_description/meshes/VXSA-300-M-7-Gripper.stl" scale="0.001 0.001 0.001"/>
      </geometry>
    </collision>
    <inertial>
      <origin rpy="0 0 1.57079632679" xyz="0.0230010000 0.0000000000 0.0115230000"/>
      <mass value="0.097666"/>
      <inertia ixx="0.0000326800" ixy="0.0000000000" ixz="0.0000000000" iyy="0.0000243600" iyz="0.0000002785" izz="0.0000211900"/>
    </inertial>
  </link>
  <!-- Fixed joint to End Effector-->
  <joint name="tcp_joint" type="fixed">
    <axis xyz="1 0 0"/>
    <origin rpy="0 0 0" xyz="0.042825 0 0"/>
    <parent link="manipulator/base_gripper_link"/>
    <child link="manipulator/end_effector_link"/>
  </joint>
  <!-- End Effector Frame-->
  <link name="manipulator/end_effector_link">
    <inertial>
      <mass value="0.001"/>
      <inertia ixx="0.0001" ixy="0" ixz="0" iyy="0.0001" iyz="0" izz="0.0001"/>
    </inertial>
  </link>
  <!-- ############################################################################################# -->
  <!-- ############################################################################################# -->
  <!-- ############################################################################################# -->
  <!-- Joint between EE and Gripper Prop (Prop of gripper motor) -->
  <joint name="gripper_joint" type="fixed">
    <!-- continuous-->
    <axis xyz="1 0 0"/>
    <limit effort="100" velocity="3.14159265359"/>
    <origin rpy="0 0 0" xyz="0.005675 0 0"/>
    <parent link="manipulator/end_effector_link"/>
    <child link="manipulator/gripper_prop_link"/>
  </joint>
  <!-- Gripper Prop Link Description-->
  <link name="manipulator/gripper_prop_link">
    <visual>
      <origin rpy="0 0 1.57079632679" xyz="-0.0685 0 0"/>
      <geometry>
        <mesh filename="package://manipulator_unal_description/meshes/VXSA-300-M-8-Gripper-Prop.stl" scale="0.001 0.001 0.001"/>
      </geometry>
      <material name="interbotix_black"/>
    </visual>
    <collision>
      <origin rpy="0 0 1.57079632679" xyz="-0.0685 0 0"/>
      <geometry>
        <mesh filename="package://manipulator_unal_description/meshes/VXSA-300-M-8-Gripper-Prop.stl" scale="0.001 0.001 0.001"/>
      </geometry>
    </collision>
    <inertial>
      <origin rpy="0 0 1.57079632679" xyz="0.0023780000 0.0000000285 0.0000000000"/>
      <mass value="0.008009"/>
      <inertia ixx="0.0000020386" ixy="0.0000000000" ixz="0.0000006559" iyy="0.0000042979" iyz="0.0000000000" izz="0.0000023796"/>
    </inertial>
  </link>
  <!-- Gripper Bar Fixed Joint (attaching EE and gripper bar)-->
  <joint name="gripper_bar_joint" type="fixed">
    <axis xyz="1 0 0"/>
    <origin rpy="0 0 0" xyz="0 0 0"/>
    <parent link="manipulator/end_effector_link"/>
    <child link="manipulator/gripper_bar_link"/>
  </joint>
  <!-- Gripper Bar Link Description-->
  <link name="manipulator/gripper_bar_link">
    <visual>
      <origin rpy="0 0 1.57079632679" xyz="-0.063 0 0"/>
      <geometry>
        <mesh filename="package://manipulator_unal_description/meshes/VXSA-300-M-9-Gripper-Bar.stl" scale="0.001 0.001 0.001"/>
      </geometry>
      <material name="interbotix_black"/>
    </visual>
    <collision>
      <origin rpy="0 0 1.57079632679" xyz="-0.063 0 0"/>
      <geometry>
        <mesh filename="package://manipulator_unal_description/meshes/VXSA-300-M-9-Gripper-Bar.stl" scale="0.001 0.001 0.001"/>
      </geometry>
    </collision>
    <inertial>
      <origin rpy="0 0 1.57079632679" xyz="0.0067940000 -0.0000004272 -0.0007760000"/>
      <mass value="0.150986"/>
      <inertia ixx="0.0000789500" ixy="-0.0000000012" ixz="0.0000001341" iyy="0.0003283000" iyz="0.0000017465" izz="0.0003095000"/>
    </inertial>
  </link>
  <!-- Fixed joint bewteen bar link and TCP of the bar-->
  <joint name="tcp_bar" type="fixed">
    <axis xyz="1 0 0"/>
    <origin rpy="0 0 0" xyz="0.025875 0 0"/>
    <parent link="manipulator/gripper_bar_link"/>
    <child link="manipulator/tcp_bar_link"/>
  </joint>
  <!-- TCP of the gripper bar Link Description-->
  <link name="manipulator/tcp_bar_link">
    <inertial>
      <mass value="0.001"/>
      <inertia ixx="0.0001" ixy="0.0" ixz="0.0" iyy="0.0001" iyz="0.0" izz="0.0001"/>
    </inertial>
  </link>
  <!-- ############################################################################################# -->
  <!-- ############################################################################################# -->
  <!-- Left Finger Joint ( Attaching the gripper bar TCP to the left finger link)-->
  <joint name="left_finger_joint" type="prismatic">
    <axis xyz="0 1 0"/>
    <limit effort="10" lower="-0.018" upper="0.018" velocity="1"/>
    <origin rpy="0 0 0" xyz="0 0.039 0"/>
    <parent link="manipulator/tcp_bar_link"/>
    <child link="manipulator/left_finger_link"/>
  </joint>
  <!-- Left Finger Link description-->
  <link name="manipulator/left_finger_link">
    <visual>
      <origin rpy="1.57079632679 -3.14159265359 1.57079632679" xyz="-0.0404 -0.0575 0"/>
      <geometry>
        <mesh filename="package://manipulator_unal_description/meshes/VXSA-300-M-10-Finger.stl" scale="0.001 0.001 0.001"/>
      </geometry>
      <material name="interbotix_black"/>
    </visual>
    <collision>
      <origin rpy="1.57079632679 -3.14159265359 1.57079632679" xyz="-0.0404 -0.0575 0"/>
      <geometry>
        <mesh filename="package://manipulator_unal_description/meshes/VXSA-300-M-10-Finger.stl" scale="0.001 0.001 0.001"/>
      </geometry>
    </collision>
    <inertial>
      <origin rpy="3.14159265359 3.14159265359 1.57079632679" xyz="0.0173440000 -0.0060692000 0.0000000000"/>
      <mass value="0.034796"/>
      <inertia ixx="0.0000243300" ixy="-0.0000024004" ixz="0.0000000000" iyy="0.0000125500" iyz="0.0000000000" izz="0.0000141700"/>
    </inertial>
  </link>
  <!-- Right Finger Joint ( Attaching the gripper bar TCP to the right finger link)-->
  <joint name="right_finger_joint" type="prismatic">
    <axis xyz="0 1 0"/>
    <limit effort="10" lower="-0.018" upper="0.018" velocity="1"/>
    <origin rpy="0 0 0" xyz="0 -0.039 0"/>
    <parent link="manipulator/tcp_bar_link"/>
    <child link="manipulator/right_finger_link"/>
  </joint>
  <!-- Right Finger Link description -->
  <link name="manipulator/right_finger_link">
    <visual>
      <origin rpy="-1.57079632679 3.14159265359 -1.57079632679" xyz="-0.0404 0.0575 0 "/>
      <geometry>
        <mesh filename="package://manipulator_unal_description/meshes/VXSA-300-M-10-Finger.stl" scale="0.001 0.001 0.001"/>
      </geometry>
      <material name="interbotix_black"/>
    </visual>
    <collision>
      <origin rpy="-1.57079632679 3.14159265359 -1.57079632679" xyz="-0.0404 0.0575 0 "/>
      <geometry>
        <mesh filename="package://manipulator_unal_description/meshes/VXSA-300-M-10-Finger.stl" scale="0.001 0.001 0.001"/>
      </geometry>
    </collision>
    <inertial>
      <origin rpy="0 3.14159265359 1.57079632679" xyz="0.0173440000 0.0060692000  0.0000000000"/>
      <mass value="0.034796"/>
      <inertia ixx="0.0000243300" ixy="0.0000024001" ixz="0.0000000000" iyy="0.0000125500" iyz="0.0000000000" izz="0.0000141700"/>
    </inertial>
  </link>
  <!-- Fixed joint attaching the gripper bar TCP frame to the gripper TCP-->
  <joint name="tcp_gripper_joint" type="fixed">
    <axis xyz="1 0 0"/>
    <origin rpy="0 0 0" xyz="0.0385 0 0"/>
    <parent link="manipulator/tcp_bar_link"/>
    <child link="manipulator/tcp_gripper_link"/>
  </joint>
  <!-- Gripper TCP Link description-->
  <link name="manipulator/tcp_gripper_link">
    <inertial>
      <mass value="0.001"/>
      <inertia ixx="0.0001" ixy="0" ixz="0" iyy="0.0001" iyz="0" izz="0.0001"/>
    </inertial>
  </link>
  <!-- Waist Tranmission -->
  <transmission name="trans_waist">
    <type>transmission_interface/SimpleTransmission</type>
    <joint name="waist_joint">
      <hardwareInterface>hardware_interface/EffortJointInterface</hardwareInterface>
    </joint>
    <actuator name="waist_motor">
      <mechanicalReduction>1</mechanicalReduction>
    </actuator>
  </transmission>
  <!-- Shoulder Tranmission -->
  <transmission name="trans_shoulder">
    <type>transmission_interface/SimpleTransmission</type>
    <joint name="shoulder_joint">
      <hardwareInterface>hardware_interface/EffortJointInterface</hardwareInterface>
    </joint>
    <actuator name="shoulder_motor">
      <mechanicalReduction>1</mechanicalReduction>
    </actuator>
  </transmission>
  <!-- Elbow Tranmission -->
  <transmission name="trans_elbow">
    <type>transmission_interface/SimpleTransmission</type>
    <joint name="elbow_joint">
      <hardwareInterface>hardware_interface/EffortJointInterface</hardwareInterface>
    </joint>
    <actuator name="elbow_motor">
      <mechanicalReduction>1</mechanicalReduction>
    </actuator>
  </transmission>
  <!-- Upper Forearm Tranmission -->
  <transmission name="trans_upper_forearm">
    <type>transmission_interface/SimpleTransmission</type>
    <joint name="upper_forearm_joint">
      <hardwareInterface>hardware_interface/EffortJointInterface</hardwareInterface>
    </joint>
    <actuator name="upper_forearm_motor">
      <mechanicalReduction>1</mechanicalReduction>
    </actuator>
  </transmission>
  <!-- Lower Forearm Tranmission -->
  <transmission name="trans_lower_forearm_joint">
    <type>transmission_interface/SimpleTransmission</type>
    <joint name="lower_forearm_joint">
      <hardwareInterface>hardware_interface/EffortJointInterface</hardwareInterface>
    </joint>
    <actuator name="lower_forearm_joint_motor">
      <mechanicalReduction>1</mechanicalReduction>
    </actuator>
  </transmission>
  <!-- Wrist Tranmission -->
  <transmission name="trans_wrist_joint">
    <type>transmission_interface/SimpleTransmission</type>
    <joint name="wrist_joint">
      <hardwareInterface>hardware_interface/EffortJointInterface</hardwareInterface>
    </joint>
    <actuator name="wrist_joint_motor">
      <mechanicalReduction>1</mechanicalReduction>
    </actuator>
  </transmission>
  <!-- Gripper Prop Tranmission 
    <transmission name="trans_gripper">
        <type>transmission_interface/SimpleTransmission</type>
        <joint name="gripper_joint">
            <hardwareInterface>hardware_interface/EffortJointInterface</hardwareInterface>
        </joint>
        <actuator name="gripper_motor">
            <mechanicalReduction>1</mechanicalReduction>
        </actuator>
    </transmission>
    -->
  <!-- Left Finger Tranmission -->
  <transmission name="trans_left_finger">
    <type>transmission_interface/SimpleTransmission</type>
    <joint name="left_finger_joint">
      <hardwareInterface>hardware_interface/EffortJointInterface</hardwareInterface>
    </joint>
    <actuator name="left_finger_motor">
      <mechanicalReduction>1</mechanicalReduction>
    </actuator>
  </transmission>
  <!-- Right Finger Tranmission -->
  <transmission name="trans_right_finger">
    <type>transmission_interface/SimpleTransmission</type>
    <joint name="right_finger_joint">
      <hardwareInterface>hardware_interface/EffortJointInterface</hardwareInterface>
    </joint>
    <actuator name="right_finger_motor">
      <mechanicalReduction>1</mechanicalReduction>
    </actuator>
  </transmission>
  <gazebo>
    <plugin filename="libgazebo_ros_control.so" name="gazebo_ros_control">
      <robotSimType>gazebo_ros_control/DefaultRobotHWSim</robotSimType>
    </plugin>
  </gazebo>
  <gazebo reference="manipulator/base_link">
    <material>Gazebo/Black</material>
    <selfCollide>True</selfCollide>
  </gazebo>
  <gazebo reference="manipulator/shoulder_link">
    &gt;
        
    <material>Gazebo/Blue</material>
    <selfCollide>True</selfCollide>
  </gazebo>
  <gazebo reference="manipulator/upper_arm_link">
    <material>Gazebo/DarkGrey</material>
    <selfCollide>True</selfCollide>
  </gazebo>
  <gazebo reference="manipulator/upper_forearm_link">
    <material>Gazebo/Orange</material>
    <selfCollide>True</selfCollide>
  </gazebo>
  <gazebo reference="manipulator/lower_forearm_link">
    <material>Gazebo/Grey</material>
    <selfCollide>True</selfCollide>
  </gazebo>
  <gazebo reference="manipulator/wrist_link">
    <material>Gazebo/Indigo</material>
    <selfCollide>True</selfCollide>
  </gazebo>
  <gazebo reference="manipulator/base_gripper_link">
    <material>Gazebo/Black</material>
    <selfCollide>True</selfCollide>
  </gazebo>
  <gazebo reference="manipulator/gripper_bar_link">
    <material>Gazebo/Green</material>
    <selfCollide>True</selfCollide>
  </gazebo>
  <gazebo reference="manipulator/left_finger_link">
    <material>Gazebo/Red</material>
    <selfCollide>True</selfCollide>
  </gazebo>
  <gazebo reference="manipulator/right_finger_link">
    <material>Gazebo/Red</material>
    <selfCollide>True</selfCollide>
  </gazebo>
  <!--  disableFixedJointLumping  
    <gazebo reference="tcp_joint">
        <disableFixedJointLumping>true</disableFixedJointLumping>
    </gazebo>
    
    <gazebo reference="gripper_bar_joint">
        <disableFixedJointLumping>true</disableFixedJointLumping>
    </gazebo>
    
    <gazebo reference="tcp_bar">
        <disableFixedJointLumping>true</disableFixedJointLumping>
    </gazebo>
    
    <gazebo reference="tcp_gripper_joint">
        <disableFixedJointLumping>true</disableFixedJointLumping>
    </gazebo>
    -->
</robot>
